Workbook

Sheet Cover
B2: 3-STATEMENT MODEL BUILD INSTRUCTIONS
B3: By Kristen Gallagher
B5: 1. GET DATA | F5: RULES:
B7: 1 | C7: Go to sec.gov/cgi-bin/browse-edgar | F7: Every query starts with let and ends with in Output
B8: 2 | C8: Search "Company Name" or ticker | F8: Every line except the last ends with a comma
B9: 3 | C9: Filter to Annual Reports (10-K) | F9: Tag names are case sensitive; must match exactly
B10: 4 | C10: Click the most recent 10-K filing | F10: Only one "in" statement at the very end
B11: 5 | C11: Click Sections: Item 8: Financial Statements to review the raw data | F11: TO CHANGE COMPANY:
B13: 2. SET UP POWER QUERY IN EXCEL | F13: Replace CIK number in the URL with the new company's CIK from EDGAR. Everything else stays the same.
B15: 1 | C15: Open Excel
B16: 2 | C16: Click Data tab
B17: 3 | C17: Click Get Data (Power Query)
B18: 4 | C18: Click Blank Query
B19: 5 | C19: Click Advanced Editor
B20: 6 | C20: Delete everything in the editor
B22: 3. WRITE THE QUERY
B24: 1 | C24: The SEC stores all financial data in a JSON file at:
B25: 2 | C25: https://data.sec.gov/api/xbrl/companyfacts/CIK0001823945.json
B26: 3 | C26: Every line item follows the same 4-step pattern:
C28: a) Get list:
C29: XList = Table.FromList(GAAP[TagName][units][USD], Splitter.SplitByNothing(), {"Record"})
C30: b) Expand fields:
C31: XExp = Table.ExpandRecordColumn(XList, "Record", {"end", "val", "form", "fp"}, {"Date", "Value", "Form", "Period"})
C32: c) Filter for annual only:
C33: XAnnual = Table.SelectRows(XExp, each [Form] = "10-K" and [Period] = "FY")
C34: d) Label it:
C35: XFinal = Table.AddColumn(XAnnual, "Metric", each "NameLabel")
C36: XFinal2 = Table.Distinct(XFinal, {"Date"})
B38: 4. PULL TAGS
C40: Income Statement: | D40: Balance Sheet:
C41: Revenues | D41: Assets
C42: NetIncomeLoss | D42: Liabilities
C43: OperatingIncomeLoss | D43: LongTermDebt
C44: LaborAndRelatedExpense | D44: StockholdersEquity
C45: GeneralAndAdministrativeExpense | D45: CashAndCashEquivalentsAtCarryingValue
C46: AmortizationOfIntangibleAssets | D46: Cash Flow:
C47: InterestExpense | D47: NetCashProvidedByUsedInOperatingActivities
C48: IncomeTaxExpenseBenefit | D48: NetCashProvidedByUsedInInvestingActivities
D49: NetCashProvidedByUsedInFinancingActivities
B51: 5. LOAD DATA INTO EXCEL
...

Sheet STMT
D2: Historical Period | K2: Forecasted Period
C3: Blue Owl Capital (OWL) | D3: 2019-12-31 | E3: 2020-12-31 | F3: 2021-12-31 | G3: 2022-12-31 | H3: 2023-12-31 | I3: 2024-12-31 | J3: 2025-12-31 | K3: 46387 | L3: 46752 | M3: 47118 | N3: 47483 | O3: 47848
C4: Dollars in Thousands, Except Per Share Data | D4: =IF(E78=0, "ok", "X") -> X | E4: =IF(F78=0, "ok", "X") -> ok | F4: =IF(G78=0, "ok", "X") -> ok | G4: =IF(H78=0, "ok", "X") -> ok | H4: =IF(I78=0, "ok", "X") -> ok | I4: =IF(J78=0, "ok", "X") -> ok | J4: =IF(K78=0, "ok", "X") -> ok
C6: Assumptions
C8: Growth Rate
C10: Revenue Growth (% Change) | E10: =(E22-D22)/E22 -> 0.23603467 | F10: =(F22-E22)/F22 -> 0.69678156 | G10: =(G22-F22)/G22 -> 0.39850714 | H10: =(H22-G22)/H22 -> 0.20898841 | I10: =(I22-H22)/I22 -> 0.24562707 | J10: =(J22-I22)/J22 -> 0.20024925 | M10: AUM Growth: 40% by 2028
C11: Compensation (% of Revenue) | E11: =ABS(D25/D22) -> 0.58565889 | F11: =ABS(E25/E22) -> 0.96363709 | G11: =ABS(F25/F22) -> 1.817002 | H11: =ABS(G25/G22) -> 0.65318802 | I11: =ABS(H25/H22) -> 0.50279393 | J11: =ABS(I25/I22) -> 0.44326524 | M11: AUM: $251B → $500B+ by 2029 : 2x+ growth, ~15% CAGR
C12: General & Administrative (% of Revenue) | E12: =ABS(D27/D22) -> 0.27094577 | F12: =ABS(E27/E22) -> 0.27144487 | G12: =ABS(F27/F22) -> 0.17025336 | H12: =ABS(G27/G22) -> 0.16106188 | I12: =ABS(H27/H22) -> 0.14022169 | J12: =ABS(I27/I22) -> 0.17989289 | M12: FRE Management Fees: $2.0B → $5.1B+ by 2029 : 20%+ CAGR
C13: Depreciation & Amortization (% of Revenue) | E13: =ABS(D26/D22) -> 0 | F13: =ABS(E26/E22) -> 0 | G13: =ABS(F26/F22) -> 0.13823527 | H13: =ABS(G26/G22) -> 0.18756288 | I13: =ABS(H26/H22) -> 0.1734463 | J13: =ABS(I26/I22) -> 0.11250891 | M13: Fee Related Earnings: $1.3B → $3.1B+ by 2029 : 20%+ CAGR
C14: Interest (% of Debt) | E14: =D34/D28 -> 0.040750414 | F14: =E34/E28 -> 0.077188843 | G14: =F34/F28 -> 0.015575523 | H14: =G34/G28 -> 0.0437748 | I14: =H34/H28 -> 0.053541115 | J14: =J34/I28 -> 0.096972766
C15: Tax Rate (% of Earnings Before Tax) | E15: =E39/E37 -> 0.0012357196 | F15: =F39/F37 -> 0.034919306 | G15: =G39/G37 -> 0.18905573 | H15: =H39/H37 -> 0.10393532 | I15: =I39/I37 -> 0.10396225 | J15: =J39/J37 -> 0.12193923
C16: Capital Expenditures ($000's)
C17: Debt Issuance (Repayment) ($000's)
C18: Equity Issued (Repaid) ($000's)
C20: Income Statement
C21: REVENUE
B22: Revenue | C22: Total Revenue | D22: =IFERROR(GETPIVOTDATA("Value",Pivot!$B2,"Metric",$B22,"Date",D$3),0) -> 190850000 | E22: =IFERROR(GETPIVOTDATA("Value",Pivot!$B2,"Metric",$B22,"Date",E$3),0) -> 249815000 | F22: =IFERROR(GETPIVOTDATA("Value",Pivot!$B2,"Metric",$B22,"Date",F$3),0) -> 823878000 | G22: =IFERROR(GETPIVOTDATA("Value",Pivot!$B2,"Metric",$B22,"Date",G$3),0) -> 1369722000 | H22: =IFERROR(GETPIVOTDATA("Value",Pivot!$B2,"Metric",$B22,"Date",H$3),0) -> 1731608000 | I22: =IFERROR(GETPIVOTDATA("Value",Pivot!$B2,"Metric",$B22,"Date",I$3),0) -> 2295427000 | J22: =IFERROR(GETPIVOTDATA("Value",Pivot!$B2,"Metric",$B22,"Date",J$3),0) -> 2870178000
C24: EXPENSES
B25: Compensation | C25: Compensation | D25: =-IFERROR(GETPIVOTDATA("Value",Pivot!$B$2,"Metric",$B25,"Date",D$3),0) -> -111773000 | E25: =-IFERROR(GETPIVOTDATA("Value",Pivot!$B$2,"Metric",$B25,"Date",E$3),0) -> -240731000 | F25: =-IFERROR(GETPIVOTDATA("Value",Pivot!$B$2,"Metric",$B25,"Date",F$3),0) -> -1496988000 | G25: =-IFERROR(GETPIVOTDATA("Value",Pivot!$B$2,"Metric",$B25,"Date",G$3),0) -> -894686000 | H25: =-IFERROR(GETPIVOTDATA("Value",Pivot!$B$2,"Metric",$B25,"Date",H$3),0) -> -870642000 | I25: =-IFERROR(GETPIVOTDATA("Value",Pivot!$B$2,"Metric",$B25,"Date",I$3),0) -> -1017483000 | J25: =-IFERROR(GETPIVOTDATA("Value",Pivot!$B$2,"Metric",$B25,"Date",J$3),0) -> -1307040000
B26: DepreciationAndAmortization | C26: Depreciation & Amortization of Intangible Assets | D26: =-IFERROR(GETPIVOTDATA("Value",Pivot!$B$2,"Metric",$B26,"Date",D$3),0) -> 0 | E26: =-IFERROR(GETPIVOTDATA("Value",Pivot!$B$2,"Metric",$B26,"Date",E$3),0) -> 0 | F26: =-IFERROR(GETPIVOTDATA("Value",Pivot!$B$2,"Metric",$B26,"Date",F$3),0) -> -113889000 | G26: =-IFERROR(GETPIVOTDATA("Value",Pivot!$B$2,"Metric",$B26,"Date",G$3),0) -> -256909000 | H26: =-IFERROR(GETPIVOTDATA("Value",Pivot!$B$2,"Metric",$B26,"Date",H$3),0) -> -300341000 | I26: =-IFERROR(GETPIVOTDATA("Value",Pivot!$B$2,"Metric",$B26,"Date",I$3),0) -> -258256000 | J26: =-IFERROR(GETPIVOTDATA("Value",Pivot!$B$2,"Metric",$B26,"Date",J$3),0) -> -358952000
B27: GeneralAndAdministrativeExpense | C27: General & Administrative | D27: =-IFERROR(GETPIVOTDATA("Value",Pivot!$B$2,"Metric",$B27,"Date",D$3),0) -> -51710000 | E27: =-IFERROR(GETPIVOTDATA("Value",Pivot!$B$2,"Metric",$B27,"Date",E$3),0) -> -67811000 | F27: =-IFERROR(GETPIVOTDATA("Value",Pivot!$B$2,"Metric",$B27,"Date",F$3),0) -> -140268000 | G27: =-IFERROR(GETPIVOTDATA("Value",Pivot!$B$2,"Metric",$B27,"Date",G$3),0) -> -220610000 | H27: =-IFERROR(GETPIVOTDATA("Value",Pivot!$B$2,"Metric",$B27,"Date",H$3),0) -> -242809000 | I27: =-IFERROR(GETPIVOTDATA("Value",Pivot!$B$2,"Metric",$B27,"Date",I$3),0) -> -412931000 | J27: =-IFERROR(GETPIVOTDATA("Value",Pivot!$B$2,"Metric",$B27,"Date",J$3),0) -> -747936000
C28: Total Operating Expenses | D28: =SUM(D25:D27) -> -163483000 | E28: =SUM(E25:E27) -> -308542000 | F28: =SUM(F25:F27) -> -1751145000 | G28: =SUM(G25:G27) -> -1372205000 | H28: =SUM(H25:H27) -> -1413792000 | I28: =SUM(I25:I27) -> -1688670000 | J28: =SUM(J25:J27) -> -2413928000
C30: Operating Income | D30: =D22+D28 -> 27367000 | E30: =E22+E28 -> -58727000 | F30: =F22+F28 -> -927267000 | G30: =G22+G28 -> -2483000 | H30: =H22+H28 -> 317816000 | I30: =I22+I28 -> 606757000 | J30: =J22+J28 -> 456250000
C32: OTHER INCOME (Expense)
B33: InterestAndDividendIncome | C33: Interest & Dividend Income | D33: =IFERROR(GETPIVOTDATA("Value",Pivot!$B$2,"Metric",$B33,"Date",D$3),0) -> 0 | E33: =IFERROR(GETPIVOTDATA("Value",Pivot!$B$2,"Metric",$B33,"Date",E$3),0) -> 0 | F33: =IFERROR(GETPIVOTDATA("Value",Pivot!$B$2,"Metric",$B33,"Date",F$3),0) -> 387000 | G33: =IFERROR(GETPIVOTDATA("Value",Pivot!$B$2,"Metric",$B33,"Date",G$3),0) -> 4357000 | H33: =IFERROR(GETPIVOTDATA("Value",Pivot!$B$2,"Metric",$B33,"Date",H$3),0) -> 22176000 | I33: =IFERROR(GETPIVOTDATA("Value",Pivot!$B$2,"Metric",$B33,"Date",I$3),0) -> 42172000 | J33: =IFERROR(GETPIVOTDATA("Value",Pivot!$B$2,"Metric",$B33,"Date",J$3),0) -> 45184000
B34: InterestExpense | C34: Interest Expense | D34: =-IFERROR(GETPIVOTDATA("Value",Pivot!$B$2,"Metric",$B34,"Date",D$3),0) -> -6662000 | E34: =-IFERROR(GETPIVOTDATA("Value",Pivot!$B$2,"Metric",$B34,"Date",E$3),0) -> -23816000 | F34: =-IFERROR(GETPIVOTDATA("Value",Pivot!$B$2,"Metric",$B34,"Date",F$3),0) -> -27275000 | G34: -60068000 | H34: =-IFERROR(GETPIVOTDATA("Value",Pivot!$B$2,"Metric",$B34,"Date",H$3),0) -> -75696000 | I34: -121894000 | J34: -163755000 | K34: 2022 SEC tag captures $55,711K; remaining $4,357K tagged separately per 10-K. | O34: : InterestExpenseNonoperating
B35: GainLossOnInvestments | C35: Net Gains (Losses) on Investments | D35: =IFERROR(GETPIVOTDATA("Value",Pivot!$B$2,"Metric",$B35,"Date",D$3),0) -> 0 | E35: =IFERROR(GETPIVOTDATA("Value",Pivot!$B$2,"Metric",$B35,"Date",E$3),0) -> 0 | F35: =IFERROR(GETPIVOTDATA("Value",Pivot!$B$2,"Metric",$B35,"Date",F$3),0) -> -3526000 | G35: =IFERROR(GETPIVOTDATA("Value",Pivot!$B$2,"Metric",$B35,"Date",G$3),0) -> -132000 | H35: =IFERROR(GETPIVOTDATA("Value",Pivot!$B$2,"Metric",$B35,"Date",H$3),0) -> 4203000 | I35: =IFERROR(GETPIVOTDATA("Value",Pivot!$B$2,"Metric",$B35,"Date",I$3),0) -> 1713000 | J35: =IFERROR(GETPIVOTDATA("Value",Pivot!$B$2,"Metric",$B35,"Date",J$3),0) -> -7105000
B36: Hardcoded | C36: Other Items | D36: 0 | E36: 0 | F36: -909796000 | G36: 8711000 | H36: -22115000 | I36: -59520000 | J36: 17337000
C37: Pre-Tax Income | D37: =D30+D33+D34+D35+D36 -> 20705000 | E37: =E30+E33+E34+E35+E36 -> -82543000 | F37: =F30+F33+F34+F35+F36 -> -1867477000 | G37: =G30+G33+G34+G35+G36 -> -49615000 | H37: =H30+H33+H34+H35+H36 -> 246384000 | I37: =I30+I33+I34+I35+I36 -> 469228000 | J37: =J30+J33+J34+J35+J36 -> 347911000 | L37: =F37+1867477000 -> 0
B39: IncomeTaxExpense | C39: Income Taxes | D39: =IFERROR(GETPIVOTDATA("Value",Pivot!$B$2,"Metric",$B39,"Date",D$3),0) -> 240000 | E39: =IFERROR(GETPIVOTDATA("Value",Pivot!$B$2,"Metric",$B39,"Date",E$3),0) -> -102000 | F39: =IFERROR(GETPIVOTDATA("Value",Pivot!$B$2,"Metric",$B39,"Date",F$3),0) -> -65211000 | G39: =IFERROR(GETPIVOTDATA("Value",Pivot!$B$2,"Metric",$B39,"Date",G$3),0) -> -9380000 | H39: =IFERROR(GETPIVOTDATA("Value",Pivot!$B$2,"Metric",$B39,"Date",H$3),0) -> 25608000 | I39: =IFERROR(GETPIVOTDATA("Value",Pivot!$B$2,"Metric",$B39,"Date",I$3),0) -> 48782000 | J39: =IFERROR(GETPIVOTDATA("Value",Pivot!$B$2,"Metric",$B39,"Date",J$3),0) -> 42424000
B41: consolidatedNetIncome | C41: Consolidated Net Income | D41: =IFERROR(GETPIVOTDATA("Value",Pivot!$B$2,"Metric",$B41,"Date",D$3),0) -> 20465000 | E41: =IFERROR(GETPIVOTDATA("Value",Pivot!$B$2,"Metric",$B41,"Date",E$3),0) -> -82441000 | F41: =IFERROR(GETPIVOTDATA("Value",Pivot!$B$2,"Metric",$B41,"Date",F$3),0) -> -1802266000 | G41: =IFERROR(GETPIVOTDATA("Value",Pivot!$B$2,"Metric",$B41,"Date",G$3),0) -> -40235000 | H41: =IFERROR(GETPIVOTDATA("Value",Pivot!$B$2,"Metric",$B41,"Date",H$3),0) -> 220776000 | I41: =IFERROR(GETPIVOTDATA("Value",Pivot!$B$2,"Metric",$B41,"Date",I$3),0) -> 420446000 | J41: =IFERROR(GETPIVOTDATA("Value",Pivot!$B$2,"Metric",$B41,"Date",J$3),0) -> 305487000
B42: Hardcoded | C42: (- ) NCI :Net income attributable to noncontrolling interests | D42: =IFERROR(GETPIVOTDATA("Value",Pivot!$B$2,"Metric",$B42,"Date",D$3),0) -> 0 | E42: 4610000 | F42: 1426095000 | G42: 30946000 | H42: -166433000 | I42: -310862000 | J42: -226654000
B43: NetIncomeLoss | C43: Net Income to Blue Owl | D43: =IFERROR(GETPIVOTDATA("Value",Pivot!$B$2,"Metric",$B43,"Date",D$3),0) -> 22958000 | E43: =E41+E42 -> -77831000 | F43: =F41+F42 -> -376171000 | G43: =G41+G42 -> -9289000 | H43: =H41+H42 -> 54343000 | I43: =I41+I42 -> 109584000 | J43: =J41+J42 -> 78833000
C45: EBITDA | D45: =D30+D26 -> 27367000 | E45: =E30+E26 -> -58727000 | F45: =F30-F26 -> -813378000 | G45: =G30-G26 -> 254426000 | H45: =H30-H26 -> 618157000 | I45: =I30-I26 -> 865013000 | J45: =J30-J26 -> 815202000
C47: Balance Sheet
C48: ASSETS
B49: Cash | C49: Cash | D49: =IFERROR(GETPIVOTDATA("Value",Pivot!$B$2,"Metric", $B49,"Date",D$3),0) -> 0 | E49: =IFERROR(GETPIVOTDATA("Value",Pivot!$B$2,"Metric", $B49,"Date",E$3),0) -> 11630000 | F49: =IFERROR(GETPIVOTDATA("Value",Pivot!$B$2,"Metric", $B49,"Date",F$3),0) -> 42567000 | G49: =IFERROR(GETPIVOTDATA("Value",Pivot!$B$2,"Metric", $B49,"Date",G$3),0) -> 68079000 | H49: =IFERROR(GETPIVOTDATA("Value",Pivot!$B$2,"Metric", $B49,"Date",H$3),0) -> 104160000 | I49: =IFERROR(GETPIVOTDATA("Value",Pivot!$B$2,"Metric", $B49,"Date",I$3),0) -> 152089000 | J49: =IFERROR(GETPIVOTDATA("Value",Pivot!$B$2,"Metric", $B49,"Date",J$3),0) -> 194512000
B50: DueFromRelatedParties | C50: Due from Related Parties | D50: =IFERROR(GETPIVOTDATA("Value",Pivot!$B$2,"Metric", $B50,"Date",D$3),0) -> 0 | E50: =IFERROR(GETPIVOTDATA("Value",Pivot!$B$2,"Metric", $B50,"Date",E$3),0) -> 92698000 | F50: =IFERROR(GETPIVOTDATA("Value",Pivot!$B$2,"Metric", $B50,"Date",F$3),0) -> 224576000 | G50: =IFERROR(GETPIVOTDATA("Value",Pivot!$B$2,"Metric", $B50,"Date",G$3),0) -> 357921000 | H50: 367136000 | I50: 548730000 | J50: 694056000
B51: Investments | C51: Investments | D51: =IFERROR(GETPIVOTDATA("Value",Pivot!$B$2,"Metric", $B51,"Date",D$3),0) -> 0 | E51: =IFERROR(GETPIVOTDATA("Value",Pivot!$B$2,"Metric", $B51,"Date",E$3),0) -> 2678000 | F51: =IFERROR(GETPIVOTDATA("Value",Pivot!$B$2,"Metric", $B51,"Date",F$3),0) -> 12143000 | G51: =IFERROR(GETPIVOTDATA("Value",Pivot!$B$2,"Metric", $B51,"Date",G$3),0) -> 317231000 | H51: =IFERROR(GETPIVOTDATA("Value",Pivot!$B$2,"Metric", $B51,"Date",H$3),0) -> 344265000 | I51: =IFERROR(GETPIVOTDATA("Value",Pivot!$B$2,"Metric", $B51,"Date",I$3),0) -> 486945000 | J51: =IFERROR(GETPIVOTDATA("Value",Pivot!$B$2,"Metric", $B51,"Date",J$3),0) -> 484389000
B52: OperatingLeaseRightOfUseAsset | C52: Operating Lease Assets | D52: =IFERROR(GETPIVOTDATA("Value",Pivot!$B$2,"Metric", $B52,"Date",D$3),0) -> 0 | E52: =IFERROR(GETPIVOTDATA("Value",Pivot!$B$2,"Metric", $B52,"Date",E$3),0) -> 0 | F52: =IFERROR(GETPIVOTDATA("Value",Pivot!$B$2,"Metric", $B52,"Date",F$3),0) -> 86033000 | G52: =IFERROR(GETPIVOTDATA("Value",Pivot!$B$2,"Metric", $B52,"Date",G$3),0) -> 224411000 | H52: =IFERROR(GETPIVOTDATA("Value",Pivot!$B$2,"Metric", $B52,"Date",H$3),0) -> 281669000 | I52: =IFERROR(GETPIVOTDATA("Value",Pivot!$B$2,"Metric", $B52,"Date",I$3),0) -> 325090000 | J52: =IFERROR(GETPIVOTDATA("Value",Pivot!$B$2,"Metric", $B52,"Date",J$3),0) -> 456204000
...

Sheet Pivot
B2: Sum of Value | C2: Column Labels
B3: Row Labels | C3: 2019-12-31 | D3: 2020-12-31 | E3: 2021-12-31 | F3: 2022-12-31 | G3: 2023-12-31 | H3: 2024-12-31 | I3: 2025-12-31
B4: Assets | D4: 276316182 | E4: 8266398000 | F4: 8893075000 | G4: 8817621000 | H4: 10992470000 | I4: 12467684000
B5: Cash | D5: 11630000 | E5: 42567000 | F5: 68079000 | G5: 104160000 | H5: 152089000 | I5: 194512000
B6: Compensation | C6: 111773000 | D6: 240731000 | E6: 1496988000 | F6: 894686000 | G6: 870642000 | H6: 1017483000 | I6: 1307040000
B7: DepreciationAndAmortization | C7: 0 | D7: 0 | E7: 113889000 | F7: 256909000 | G7: 300341000 | H7: 258256000 | I7: 358952000
B8: FinancingCashFlow | C8: -43007000 | D8: -295000 | E8: 1348151000 | F8: -217717000 | G8: -795033000 | H8: -313481000 | I8: -943038000
B9: GeneralAndAdministrativeExpense | C9: 51710000 | D9: 67811000 | E9: 140268000 | F9: 220610000 | G9: 242809000 | H9: 412931000 | I9: 747936000
B10: IncomeTaxExpense | C10: 240000 | D10: -102000 | E10: -65211000 | F10: -9380000 | G10: 25608000 | H10: 48782000 | I10: 42424000
B11: InterestExpense | C11: 6662000 | D11: 23816000 | E11: 27275000 | F11: 55711000 | G11: 75696000
B12: InvestingCashFlow | C12: -1173000 | D12: -652000 | E12: -1598872000 | F12: -485218000 | G12: -118031000 | H12: -638145000 | I12: -270571000
B13: Liabilities | D13: 9767101 | E13: 2418828000 | F13: 3344189000 | G13: 3539690000 | H13: 5186434000 | I13: 6413485000
B14: LongTermDebt | D14: 356386000 | E14: 1174167000 | F14: 1624771000 | G14: 1681241000 | H14: 2588496000 | I14: 3324426000
B15: NetIncomeLoss | C15: 22958000 | D15: -77831000 | E15: -376171000 | F15: -9289000 | G15: 54343000 | H15: 109584000 | I15: 78833000
B16: OperatingCashFlow | C16: 44064000 | D16: 5234000 | E16: 281658000 | F16: 728447000 | G16: 949145000 | H16: 999555000 | I16: 1256032000
B17: OperatingIncomeLoss | D17: -299659
B18: StockholdersEquity | D18: 5000001 | E18: 1663567000 | F18: 1604698000 | G18: 1528239000 | H18: 2127758000 | I18: 2205362000
B19: Revenue | C19: 190850000 | D19: 249815000 | E19: 823878000 | F19: 1369722000 | G19: 1731608000 | H19: 2295427000 | I19: 2870178000
B20: MinorityInterest | D20: 6526000 | E20: 4184003000 | F20: 3944188000 | G20: 3749692000 | H20: 3678278000 | I20: 3848837000
B21: ShareBasedCompensation | C21: 0 | D21: 0 | E21: 1205336000 | F21: 420832000 | G21: 312564000 | H21: 312609000 | I21: 673524000
B22: RepaymentsOfDebt | C22: 83590000 | D22: 171458000 | E22: 577835000 | F22: 323000000 | G22: 1000000000 | H22: 1245000000 | I22: 1540000000
B23: DividendsPaid | C23: 0 | D23: 0 | E23: 47076000 | F23: 182550000 | G23: 247882000 | H23: 368331000 | I23: 546657000
B24: EPSDiluted | E24: -1.34 | F24: -0.02 | G24: 0.1 | H24: 0.2 | I24: 0.1
B25: ProceedsFromDebt | C25: 344944000 | D25: 240547000 | E25: 1390296000 | F25: 775060000 | G25: 1054800000 | H25: 2170000000 | I25: 2270000000
B26: ProceedsFromEquity | D26: 269500000
B27: DebtFairValue | F27: 1300000000 | G27: 1400000000 | H27: 2500000000 | I27: 3200000000
B28: ConsolidatedNetIncome | C28: 20465000 | D28: -82441000 | E28: -1802266000 | F28: -40235000 | G28: 220776000 | H28: 420446000 | I28: 305487000
B29: Depreciation | C29: 829000 | D29: 673000 | E29: 665000 | F29: 2304000 | G29: 10226000 | H29: 16660000 | I29: 23446000
B30: PPENet | D30: 3356000 | E30: 7951000 | F30: 71190000 | G30: 134893000 | H30: 187749000 | I30: 218941000
B31: InterestAndDividendIncome | E31: 387000 | F31: 4357000 | G31: 22176000 | H31: 42172000 | I31: 45184000
B32: GainLossOnInvestments | C32: 0 | D32: 0 | E32: -3526000 | F32: -132000 | G32: 4203000 | H32: 1713000 | I32: -7105000
B33: Investments | D33: 2678000 | E33: 12143000 | F33: 317231000 | G33: 344265000 | H33: 486945000 | I33: 484389000
B34: DueFromRelatedParties | D34: 92698000 | E34: 224576000 | F34: 357921000
B35: Goodwill | D35: 0 | E35: 4132245000 | F35: 4205159000 | G35: 4224153000 | H35: 4699465000 | I35: 5624469000
B36: OtherAssets | D36: 16469000 | E36: 38620000 | F36: 99679000 | G36: 187455000 | H36: 258748000 | I36: 382519000
B37: IntangibleAssetsNet | D37: 0 | E37: 2611411000 | F37: 2405422000 | G37: 2110008000 | H37: 2902752000 | I37: 2888800000
B38: AccruedCompensation | D38: 207957000 | E38: 155606000 | F38: 309644000 | G38: 370726000 | H38: 424024000 | I38: 525550000
B39: AccountsPayableAndOther | D39: 58415000 | E39: 68339000 | F39: 126559000 | G39: 138754000 | H39: 165953000 | I39: 163000000
B40: DeferredTaxLiabilities | D40: 0 | E40: 48962000 | F40: 41791000 | G40: 34419000 | H40: 36867000 | I40: 39663000
B41: AdditionalPaidInCapital | D41: 5260809 | E41: 2160934000 | F41: 2293903000 | G41: 2410982000 | H41: 3269239000 | I41: 3812770000
...

Sheet Query
A1: Metric | B1: Date | C1: Value
A2: Revenue | B2: 2019-12-31 | C2: 190850000
A3: Revenue | B3: 2020-12-31 | C3: 249815000
A4: Revenue | B4: 2021-12-31 | C4: 823878000
A5: Revenue | B5: 2022-12-31 | C5: 1369722000
A6: Revenue | B6: 2023-12-31 | C6: 1731608000
A7: Revenue | B7: 2024-12-31 | C7: 2295427000
A8: Revenue | B8: 2025-12-31 | C8: 2870178000
A9: NetIncomeLoss | B9: 2019-12-31 | C9: 22958000
A10: NetIncomeLoss | B10: 2020-12-31 | C10: -77831000
A11: NetIncomeLoss | B11: 2021-12-31 | C11: -376171000
A12: NetIncomeLoss | B12: 2022-12-31 | C12: -9289000
A13: NetIncomeLoss | B13: 2023-12-31 | C13: 54343000
... A263: AcquisitionPayments | B263: 2025-12-31 | C263: 244580000

Sheet Sheet1
B2: CFA Template | C2: Blue Owl Equivalent | E2: https://www.sec.gov/ix?doc=/Archives/edgar/data/0001823945/000182394526000009/owl-20251231.htm#fact-identifier-32
B3: Equity Capital | C3: Additional Paid-in Capital
B4: Retained Earnings | C4: Accumulated Deficit
B5: Shareholder's Equity | C5: Total Shareholders' Equity - Blue Owl
B6: Total Liabilities & Shareholder's Equity | C6: Total Liabilities & Shareholder's Equity
B8: Other Non-Cash & WC Changes
B9: Non-cash items:
B10: Amortization of debt discounts
B11: Non-cash interest income
B12: Deferred income taxes
B13: Change in TRA liability
B14: Change in warrant liability
B15: Change in earnout liability
B16: Net gains/losses on investments
B18: Working capital changes:
B19: Due from related parties
B20: Other assets
... B25: other names for these;
B26: Duefromrelatedparties | C26: OtherReceivables
B27: InterestExpense | C27: InterestExpenseNonoperating
B28: Other Financing Items plug handles everything else
B30: 2026 Q1 Deck
B31: RSU tax withholding ($79.6M in 2025)
B32: TRA payments ($53.5M in 2025)
B33: Share repurchases ($53.7M in 2025)
B34: Debt issuance costs ($3.4M in 2025)
B35: Earnout payments ($36.8M in 2025)
B37: Revenue Forecast | D37: Bottom-up AUM
B38: Revenue ≈ Fee-Paying AUM × Average Fee Rate
B39: From BlueOwl Q1 2026 deck:
B40: AUM: | C40: $315B
B41: Fee-Paying AUM (FPAUM): | C41: $225B | D41: (this is the number that actually matters)
B42: LTM FRE Management Fees: | C42: $2,622M
B43: So implied fee rate = $2,622M / $225B ≈ 1.17% | C43: 0.0117
